2024-12-05 13:01:02.627 | ERROR    | __main__:<module>:27 - An error has been caught in function '<module>', process 'MainProcess' (240759), thread 'MainThread' (140190522073536):
Traceback (most recent call last):

  File "/home/daoyuan_mm/miniconda3/envs/videollama/lib/python3.9/runpy.py", line 197, in _run_module_as_main
    return _run_code(code, main_globals, None,
           │         │     └ {'__name__': '__main__', '__doc__': None, '__package__': '', '__loader__': <_frozen_importlib_external.SourceFileLoader objec...
           │         └ <code object <module> at 0x7f8098ca8450, file "/home/daoyuan_mm/.vscode-server/extensions/ms-python.debugpy-2024.0.0-linux-x6...
           └ <function _run_code at 0x7f8098ca59d0>
  File "/home/daoyuan_mm/miniconda3/envs/videollama/lib/python3.9/runpy.py", line 87, in _run_code
    exec(code, run_globals)
         │     └ {'__name__': '__main__', '__doc__': None, '__package__': '', '__loader__': <_frozen_importlib_external.SourceFileLoader objec...
         └ <code object <module> at 0x7f8098ca8450, file "/home/daoyuan_mm/.vscode-server/extensions/ms-python.debugpy-2024.0.0-linux-x6...

  File "/home/daoyuan_mm/.vscode-server/extensions/ms-python.debugpy-2024.0.0-linux-x64/bundled/libs/debugpy/adapter/../../debugpy/launcher/../../debugpy/__main__.py", line 39, in <module>
    cli.main()
    │   └ <function main at 0x7f809780f280>
    └ <module 'debugpy.server.cli' from '/home/daoyuan_mm/.vscode-server/extensions/ms-python.debugpy-2024.0.0-linux-x64/bundled/li...

  File "/home/daoyuan_mm/.vscode-server/extensions/ms-python.debugpy-2024.0.0-linux-x64/bundled/libs/debugpy/adapter/../../debugpy/launcher/../../debugpy/../debugpy/server/cli.py", line 430, in main
    run()
    └ <function run_file at 0x7f809780f040>

  File "/home/daoyuan_mm/.vscode-server/extensions/ms-python.debugpy-2024.0.0-linux-x64/bundled/libs/debugpy/adapter/../../debugpy/launcher/../../debugpy/../debugpy/server/cli.py", line 284, in run_file
    runpy.run_path(target, run_name="__main__")
    │     │        └ '/home/daoyuan_mm/data_juicer/tools/process_data.py'
    │     └ <function run_path at 0x7f8097d0d820>
    └ <module '_pydevd_bundle.pydevd_runpy' from '/home/daoyuan_mm/.vscode-server/extensions/ms-python.debugpy-2024.0.0-linux-x64/b...

  File "/home/daoyuan_mm/.vscode-server/extensions/ms-python.debugpy-2024.0.0-linux-x64/bundled/libs/debugpy/_vendored/pydevd/_pydevd_bundle/pydevd_runpy.py", line 321, in run_path
    return _run_module_code(code, init_globals, run_name,
           │                │     │             └ '__main__'
           │                │     └ None
           │                └ <code object <module> at 0x7f80977253a0, file "/home/daoyuan_mm/data_juicer/tools/process_data.py", line 4>
           └ <function _run_module_code at 0x7f8097cfee50>

  File "/home/daoyuan_mm/.vscode-server/extensions/ms-python.debugpy-2024.0.0-linux-x64/bundled/libs/debugpy/_vendored/pydevd/_pydevd_bundle/pydevd_runpy.py", line 135, in _run_module_code
    _run_code(code, mod_globals, init_globals,
    │         │     │            └ None
    │         │     └ {'__name__': '__main__', '__doc__': None, '__package__': '', '__loader__': None, '__spec__': None, '__file__': '/home/daoyuan...
    │         └ <code object <module> at 0x7f80977253a0, file "/home/daoyuan_mm/data_juicer/tools/process_data.py", line 4>
    └ <function _run_code at 0x7f8097cfeb80>

  File "/home/daoyuan_mm/.vscode-server/extensions/ms-python.debugpy-2024.0.0-linux-x64/bundled/libs/debugpy/_vendored/pydevd/_pydevd_bundle/pydevd_runpy.py", line 124, in _run_code
    exec(code, run_globals)
         │     └ {'__name__': '__main__', '__doc__': None, '__package__': '', '__loader__': None, '__spec__': None, '__file__': '/home/daoyuan...
         └ <code object <module> at 0x7f80977253a0, file "/home/daoyuan_mm/data_juicer/tools/process_data.py", line 4>

> File "/home/daoyuan_mm/data_juicer/tools/process_data.py", line 27, in <module>
    main()
    └ <function main at 0x7f7d97727040>

  File "/home/daoyuan_mm/data_juicer/tools/process_data.py", line 17, in main
    cfg = init_configs()
          └ <function init_configs at 0x7f7fc0c620d0>

  File "/home/daoyuan_mm/data_juicer/data_juicer/config/config.py", line 339, in init_configs
    cfg = init_setup_from_cfg(cfg)
          │                   └ Namespace(config=[Path_fr(/home/daoyuan_mm/data_juicer/HumanVBenchRecipe/HumanCentricVideoAnnotationPipeline/process.yaml)], ...
          └ <function init_setup_from_cfg at 0x7f7fbf899d30>

  File "/home/daoyuan_mm/data_juicer/data_juicer/config/config.py", line 499, in init_setup_from_cfg
    args['text_key'] = text_key
    │                  └ 'text'
    └ '/mnt/daoyuan_open_research/zt_data/pt_model/sharegpt4video-8b'

TypeError: 'str' object does not support item assignment
